Workbook

Sheet Watchlist
A1: Upstox Watchlist
A2: Fill in the Symbol column (A) only, starting row 5, with NSE trading symbols (e.g. RELIANCE, TCS). Run update_excel.py to populate columns B-I via the Upstox LTP API. Do not edit columns B-I directly - they are overwritten on each run.
A4: Symbol | B4: Instrument Key | C4: LTP | D4: LTQ | E4: Volume | F4: Prev Close | G4: Change | H4: Change % | I4: Last Updated
A5: MAHKTECH | B5: NSE_EQ|INF769K01HS7 | C5: 23.23 | D5: 8 | E5: 937285 | F5: 23.1 | G5: =IF(A5="","",C5-F5) | H5: =IF(OR(A5="",F5=0),"",(C5-F5)/F5) | I5: 2026-08-19 17:54:59
A6: HNGSNGBEES | B6: NSE_EQ|INF204KB19I1 | C6: 479.5 | D6: 2 | E6: 77201 | F6: 481.22 | I6: 2026-08-19 17:54:59
A7: GSEC10IETF | B7: NSE_EQ|INF109KC18O0 | C7: 266.89 | D7: 9 | E7: 575 | F7: 265.49 | I7: 2026-08-19 17:54:59
A8: SETF10GILT | B8: NSE_EQ|INF200KA1JT1 | C8: 265.4 | D8: 41 | E8: 284 | F8: 265.39 | G8: =IF(A8="","",C8-F8) | H8: =IF(OR(A8="",F8=0),"",(C8-F8)/F8) | I8: 2026-08-19 17:54:59
A9: LTGILTBEES | B9: NSE_EQ|INF204KB1882 | C9: 30.04 | D9: 3000 | E9: 561225 | F9: 30.02 | G9: =IF(A9="","",C9-F9) | H9: =IF(OR(A9="",F9=0),"",(C9-F9)/F9) | I9: 2026-08-19 17:54:59
A10: LICNETFGSC | B10: NSE_EQ|INF767K01MV5 | C10: 29.9 | D10: 3 | E10: 68488 | F10: 29.51 | G10: =IF(A10="","",C10-F10) | H10: =IF(OR(A10="",F10=0),"",(C10-F10)/F10) | I10: 2026-08-19 17:54:59
A11: GILT5YBEES | B11: NSE_EQ|INF204KC1030 | C11: 66.27 | D11: 771 | E11: 69863 | F11: 66.23 | G11: =IF(A11="","",C11-F11) | H11: =IF(OR(A11="",F11=0),"",(C11-F11)/F11) | I11: 2026-08-19 17:54:59
A12: PVTBANIETF | B12: NSE_EQ|INF109KC18U7 | C12: 27.65 | D12: 100 | E12: 1210942 | F12: 27.67 | G12: =IF(A12="","",C12-F12) | H12: =IF(OR(A12="",F12=0),"",(C12-F12)/F12) | I12: 2026-08-19 17:54:59
A13: PVTBANKADD | B13: NSE_EQ|INF740KA1TA7 | C13: 27.82 | D13: 314 | E13: 44088 | F13: 27.82 | G13: =IF(A13="","",C13-F13) | H13: =IF(OR(A13="",F13=0),"",(C13-F13)/F13) | I13: 2026-08-19 17:54:59
A14: CONSUMBEES | B14: NSE_EQ|INF204KA1LD7 | C14: 133 | D14: 78 | E14: 41453 | F14: 134.2 | G14: =IF(A14="","",C14-F14) | H14: =IF(OR(A14="",F14=0),"",(C14-F14)/F14) | I14: 2026-08-19 17:54:59
A15: ALPHAETF | B15: NSE_EQ|INF769K01KU7 | C15: 26.45 | D15: 5 | E15: 341006 | F15: 26.79 | G15: =IF(A15="","",C15-F15) | H15: =IF(OR(A15="",F15=0),"",(C15-F15)/F15) | I15: 2026-08-19 17:54:59
A16: HDFCMOMENT | B16: NSE_EQ|INF179KC1HV6 | C16: 31.18 | D16: 30 | E16: 207377 | F16: 31.42 | G16: =IF(A16="","",C16-F16) | H16: =IF(OR(A16="",F16=0),"",(C16-F16)/F16) | I16: 2026-08-19 17:54:59
A17: HDFCPVTBAN | B17: NSE_EQ|INF179KC1HZ7 | C17: 27.92 | D17: 525 | E17: 222559 | F17: 27.84 | G17: =IF(A17="","",C17-F17) | H17: =IF(OR(A17="",F17=0),"",(C17-F17)/F17) | I17: 2026-08-19 17:54:59
A18: BFSI | B18: NSE_EQ|INF769K01HI8 | C18: 27.11 | D18: 25 | E18: 93175 | F18: 27.22 | G18: =IF(A18="","",C18-F18) | H18: =IF(OR(A18="",F18=0),"",(C18-F18)/F18) | I18: 2026-08-19 17:54:59
A19: BANKBEES | B19: NSE_EQ|INF204KB15I9 | C19: 592.7 | D19: 18 | E19: 360616 | F19: 594.86 | G19: =IF(A19="","",C19-F19) | H19: =IF(OR(A19="",F19=0),"",(C19-F19)/F19) | I19: 2026-08-19 17:54:59
... A25: BANKNIFTY1 | B25: NSE_EQ|INF174KA1ZB7 | C25: 59.34 | D25: 1123 | E25: 422108 | F25: 59.63 | G25: =IF(A25="","",C25-F25) | H25: =IF(OR(A25="",F25=0),"",(C25-F25)/F25) | I25: 2026-08-19 17:54:59
A26: UTIBANKETF | B26: NOT FOUND | G26: =IF(A26="","",C26-F26) | H26: =IF(OR(A26="",F26=0),"",(C26-F26)/F26)
A27: MOMOMENTUM | B27: NSE_EQ|INF247L01BK2 | C27: 62.2 | D27: 205 | E27: 53710 | F27: 63.04 | G27: =IF(A27="","",C27-F27) | H27: =IF(OR(A27="",F27=0),"",(C27-F27)/F27) | I27: 2026-08-19 17:54:59
A28: MOMENTUM | B28: NSE_EQ|INF209KB14K7 | C28: 31.25 | D28: 50 | E28: 163712 | F28: 31.47 | G28: =IF(A28="","",C28-F28) | H28: =IF(OR(A28="",F28=0),"",(C28-F28)/F28) | I28: 2026-08-19 17:54:59
A29: PSUBNKBEES | B29: NSE_EQ|INF204KB16I7 | C29: 96.13 | D29: 3200 | E29: 875252 | F29: 96.52 | G29: =IF(A29="","",C29-F29) | H29: =IF(OR(A29="",F29=0),"",(C29-F29)/F29) | I29: 2026-08-19 17:54:59
A30: PSUBNKIETF | B30: NSE_EQ|INF109KC10S8 | C30: 87.59 | D30: 3 | E30: 54357 | F30: 87.45 | G30: =IF(A30="","",C30-F30) | H30: =IF(OR(A30="",F30=0),"",(C30-F30)/F30) | I30: 2026-08-19 17:54:59
A31: NIF5GETF | B31: NOT FOUND | G31: =IF(A31="","",C31-F31) | H31: =IF(OR(A31="",F31=0),"",(C31-F31)/F31)
A32: MOHEALTH | B32: NSE_EQ|INF247L01BB1 | C32: 51.4 | D32: 2 | E32: 27562 | F32: 51.46 | G32: =IF(A32="","",C32-F32) | H32: =IF(OR(A32="",F32=0),"",(C32-F32)/F32) | I32: 2026-08-19 17:54:59
A33: FMCGIETF | B33: NSE_EQ|INF109KC19V3 | C33: 51.17 | D33: 62 | E33: 1017354 | F33: 51.35 | G33: =IF(A33="","",C33-F33) | H33: =IF(OR(A33="",F33=0),"",(C33-F33)/F33) | I33: 2026-08-19 17:54:59
A34: HEALTHIETF | B34: NSE_EQ|INF109KC1Q72 | C34: 169.24 | D34: 3 | E34: 56446 | F34: 168.95 | G34: =IF(A34="","",C34-F34) | H34: =IF(OR(A34="",F34=0),"",(C34-F34)/F34) | I34: 2026-08-19 17:54:59
A35: MIDSMALL | B35: NSE_EQ|INF769K01LJ8 | C35: 51.91 | D35: 30 | E35: 277258 | F35: 52.33 | G35: =IF(A35="","",C35-F35) | H35: =IF(OR(A35="",F35=0),"",(C35-F35)/F35) | I35: 2026-08-19 17:54:59
A36: BSE500IETF | B36: NSE_EQ|INF109KC1V59 | C36: 39.62 | D36: 44 | E36: 85980 | F36: 39.9 | G36: =IF(A36="","",C36-F36) | H36: =IF(OR(A36="",F36=0),"",(C36-F36)/F36) | I36: 2026-08-19 17:54:59
A37: HDFCPSUBK | B37: NSE_EQ|INF179KC1HW4 | C37: 86.5 | D37: 1 | E37: 33934 | F37: 87.17 | G37: =IF(A37="","",C37-F37) | H37: =IF(OR(A37="",F37=0),"",(C37-F37)/F37) | I37: 2026-08-19 17:54:59
A38: MASPTOP50 | B38: NSE_EQ|INF769K01HP3 | C38: 80.83 | D38: 35 | E38: 94313 | F38: 81.02 | G38: =IF(A38="","",C38-F38) | H38: =IF(OR(A38="",F38=0),"",(C38-F38)/F38) | I38: 2026-08-19 17:54:59
A39: MONQ50 | B39: NSE_EQ|INF247L01AU3 | C39: 151.65 | D39: 2 | E39: 134519 | F39: 151.2 | G39: =IF(A39="","",C39-F39) | H39: =IF(OR(A39="",F39=0),"",(C39-F39)/F39) | I39: 2026-08-19 17:54:59
A40: AUTOIETF | B40: NSE_EQ|INF109KC10V2 | C40: 30.2 | D40: 2 | E40: 917682 | F40: 30.4 | G40: =IF(A40="","",C40-F40) | H40: =IF(OR(A40="",F40=0),"",(C40-F40)/F40) | I40: 2026-08-19 17:54:59
A41: HDFCNIFTY | B41: NSE_EQ|INF179KC1965 | C41: 271.9 | D41: 44 | E41: 59746 | F41: 273.21 | G41: =IF(A41="","",C41-F41) | H41: =IF(OR(A41="",F41=0),"",(C41-F41)/F41) | I41: 2026-08-19 17:54:59
A42: AUTOBEES | B42: NSE_EQ|INF204KC1337 | C42: 302.5 | D42: 2 | E42: 160307 | F42: 303.77 | G42: =IF(A42="","",C42-F42) | H42: =IF(OR(A42="",F42=0),"",(C42-F42)/F42) | I42: 2026-08-19 17:54:59
A43: NIFTYBEES | B43: NSE_EQ|INF204KB14I2 | C43: 274.62 | D43: 500 | E43: 6107344 | F43: 276.1 | G43: =IF(A43="","",C43-F43) | H43: =IF(OR(A43="",F43=0),"",(C43-F43)/F43) | I43: 2026-08-19 17:54:59
... A48: NIFTYETF | B48: NSE_EQ|INF769K01EG9 | C48: 262.51 | D48: 400 | E48: 820285 | F48: 263.65 | G48: =IF(A48="","",C48-F48) | H48: =IF(OR(A48="",F48=0),"",(C48-F48)/F48) | I48: 2026-08-19 17:54:59
A49: UTINIFTETF | B49: NOT FOUND | G49: =IF(A49="","",C49-F49) | H49: =IF(OR(A49="",F49=0),"",(C49-F49)/F49)
A50: HDFCSENSEX | B50: NSE_EQ|INF179KC1HX2 | C50: 87.72 | D50: 10 | E50: 24563 | F50: 87.77 | G50: =IF(A50="","",C50-F50) | H50: =IF(OR(A50="",F50=0),"",(C50-F50)/F50) | I50: 2026-08-19 17:54:59
...

Sheet Analysis
A1: Watchlist Analysis
A2: Symbol and CMP columns are linked to the Watchlist sheet. Columns C-H are placeholders pending formulas.
A4: Symbol | B4: CMP | C4: 20 MA | D4: CMP-20MA | E4: % Change 20 MA Vs CMP | G4: PDP | H4: Change in %
A5: =Watchlist!A5 | B5: =Watchlist!C5 | C5: 23.4815 | D5: =IF(OR(B5="",C5="",C5=0),"",B5-C5) | E5: =IF(OR(B5="",C5="",C5=0),"",(B5-C5)/C5) | G5: =Watchlist!F5 | H5: =IF(OR(B5="",G5="",G5=0),"",(B5-G5)/G5)
A6: =Watchlist!A6 | B6: =Watchlist!C6 | C6: 487.1285 | D6: =IF(OR(B6="",C6="",C6=0),"",B6-C6) | E6: =IF(OR(B6="",C6="",C6=0),"",(B6-C6)/C6) | G6: =Watchlist!F6 | H6: =IF(OR(B6="",G6="",G6=0),"",(B6-G6)/G6)
A7: =Watchlist!A7 | B7: =Watchlist!C7 | C7: 264.8575 | D7: =IF(OR(B7="",C7="",C7=0),"",B7-C7) | E7: =IF(OR(B7="",C7="",C7=0),"",(B7-C7)/C7) | G7: =Watchlist!F7 | H7: =IF(OR(B7="",G7="",G7=0),"",(B7-G7)/G7)
A8: =Watchlist!A8 | B8: =Watchlist!C8 | C8: 265.7105 | D8: =IF(OR(B8="",C8="",C8=0),"",B8-C8) | E8: =IF(OR(B8="",C8="",C8=0),"",(B8-C8)/C8) | G8: =Watchlist!F8 | H8: =IF(OR(B8="",G8="",G8=0),"",(B8-G8)/G8)
A9: =Watchlist!A9 | B9: =Watchlist!C9 | C9: 29.9925 | D9: =IF(OR(B9="",C9="",C9=0),"",B9-C9) | E9: =IF(OR(B9="",C9="",C9=0),"",(B9-C9)/C9) | G9: =Watchlist!F9 | H9: =IF(OR(B9="",G9="",G9=0),"",(B9-G9)/G9)
A10: =Watchlist!A10 | B10: =Watchlist!C10 | C10: 29.5085 | D10: =IF(OR(B10="",C10="",C10=0),"",B10-C10) | E10: =IF(OR(B10="",C10="",C10=0),"",(B10-C10)/C10) | G10: =Watchlist!F10 | H10: =IF(OR(B10="",G10="",G10=0),"",(B10-G10)/G10)
A11: =Watchlist!A11 | B11: =Watchlist!C11 | C11: 66.206 | D11: =IF(OR(B11="",C11="",C11=0),"",B11-C11) | E11: =IF(OR(B11="",C11="",C11=0),"",(B11-C11)/C11) | G11: =Watchlist!F11 | H11: =IF(OR(B11="",G11="",G11=0),"",(B11-G11)/G11)
A12: =Watchlist!A12 | B12: =Watchlist!C12 | C12: 27.754 | D12: =IF(OR(B12="",C12="",C12=0),"",B12-C12) | E12: =IF(OR(B12="",C12="",C12=0),"",(B12-C12)/C12) | G12: =Watchlist!F12 | H12: =IF(OR(B12="",G12="",G12=0),"",(B12-G12)/G12)
A13: =Watchlist!A13 | B13: =Watchlist!C13 | C13: 27.8855 | D13: =IF(OR(B13="",C13="",C13=0),"",B13-C13) | E13: =IF(OR(B13="",C13="",C13=0),"",(B13-C13)/C13) | G13: =Watchlist!F13 | H13: =IF(OR(B13="",G13="",G13=0),"",(B13-G13)/G13)
A14: =Watchlist!A14 | B14: =Watchlist!C14 | C14: 134.0805 | D14: =IF(OR(B14="",C14="",C14=0),"",B14-C14) | E14: =IF(OR(B14="",C14="",C14=0),"",(B14-C14)/C14) | G14: =Watchlist!F14 | H14: =IF(OR(B14="",G14="",G14=0),"",(B14-G14)/G14)
A15: =Watchlist!A15 | B15: =Watchlist!C15 | C15: 26.3075 | D15: =IF(OR(B15="",C15="",C15=0),"",B15-C15) | E15: =IF(OR(B15="",C15="",C15=0),"",(B15-C15)/C15) | G15: =Watchlist!F15 | H15: =IF(OR(B15="",G15="",G15=0),"",(B15-G15)/G15)
A16: =Watchlist!A16 | B16: =Watchlist!C16 | C16: 30.9935 | D16: =IF(OR(B16="",C16="",C16=0),"",B16-C16) | E16: =IF(OR(B16="",C16="",C16=0),"",(B16-C16)/C16) | G16: =Watchlist!F16 | H16: =IF(OR(B16="",G16="",G16=0),"",(B16-G16)/G16)
... A25: =Watchlist!A25 | B25: =Watchlist!C25 | C25: 59.613 | D25: =IF(OR(B25="",C25="",C25=0),"",B25-C25) | E25: =IF(OR(B25="",C25="",C25=0),"",(B25-C25)/C25) | G25: =Watchlist!F25 | H25: =IF(OR(B25="",G25="",G25=0),"",(B25-G25)/G25)
A26: =Watchlist!A26 | B26: =Watchlist!C26 | G26: =Watchlist!F26 | H26: =IF(OR(B26="",G26="",G26=0),"",(B26-G26)/G26)
A27: =Watchlist!A27 | B27: =Watchlist!C27 | C27: 62.206 | D27: =IF(OR(B27="",C27="",C27=0),"",B27-C27) | E27: =IF(OR(B27="",C27="",C27=0),"",(B27-C27)/C27) | G27: =Watchlist!F27 | H27: =IF(OR(B27="",G27="",G27=0),"",(B27-G27)/G27)
A28: =Watchlist!A28 | B28: =Watchlist!C28 | C28: 31.071 | D28: =IF(OR(B28="",C28="",C28=0),"",B28-C28) | E28: =IF(OR(B28="",C28="",C28=0),"",(B28-C28)/C28) | G28: =Watchlist!F28 | H28: =IF(OR(B28="",G28="",G28=0),"",(B28-G28)/G28)
A29: =Watchlist!A29 | B29: =Watchlist!C29 | C29: 95.332 | D29: =IF(OR(B29="",C29="",C29=0),"",B29-C29) | E29: =IF(OR(B29="",C29="",C29=0),"",(B29-C29)/C29) | G29: =Watchlist!F29 | H29: =IF(OR(B29="",G29="",G29=0),"",(B29-G29)/G29)
A30: =Watchlist!A30 | B30: =Watchlist!C30 | C30: 86.4285 | D30: =IF(OR(B30="",C30="",C30=0),"",B30-C30) | E30: =IF(OR(B30="",C30="",C30=0),"",(B30-C30)/C30) | G30: =Watchlist!F30 | H30: =IF(OR(B30="",G30="",G30=0),"",(B30-G30)/G30)
A31: =Watchlist!A31 | B31: =Watchlist!C31 | G31: =Watchlist!F31 | H31: =IF(OR(B31="",G31="",G31=0),"",(B31-G31)/G31)
A32: =Watchlist!A32 | B32: =Watchlist!C32 | C32: 51.4905 | D32: =IF(OR(B32="",C32="",C32=0),"",B32-C32) | E32: =IF(OR(B32="",C32="",C32=0),"",(B32-C32)/C32) | G32: =Watchlist!F32 | H32: =IF(OR(B32="",G32="",G32=0),"",(B32-G32)/G32)
A33: =Watchlist!A33 | B33: =Watchlist!C33 | C33: 52.711 | D33: =IF(OR(B33="",C33="",C33=0),"",B33-C33) | E33: =IF(OR(B33="",C33="",C33=0),"",(B33-C33)/C33) | G33: =Watchlist!F33 | H33: =IF(OR(B33="",G33="",G33=0),"",(B33-G33)/G33)
A34: =Watchlist!A34 | B34: =Watchlist!C34 | C34: 170.022 | D34: =IF(OR(B34="",C34="",C34=0),"",B34-C34) | E34: =IF(OR(B34="",C34="",C34=0),"",(B34-C34)/C34) | G34: =Watchlist!F34 | H34: =IF(OR(B34="",G34="",G34=0),"",(B34-G34)/G34)
A35: =Watchlist!A35 | B35: =Watchlist!C35 | C35: 51.5185 | D35: =IF(OR(B35="",C35="",C35=0),"",B35-C35) | E35: =IF(OR(B35="",C35="",C35=0),"",(B35-C35)/C35) | G35: =Watchlist!F35 | H35: =IF(OR(B35="",G35="",G35=0),"",(B35-G35)/G35)
A36: =Watchlist!A36 | B36: =Watchlist!C36 | C36: 39.6685 | D36: =IF(OR(B36="",C36="",C36=0),"",B36-C36) | E36: =IF(OR(B36="",C36="",C36=0),"",(B36-C36)/C36) | G36: =Watchlist!F36 | H36: =IF(OR(B36="",G36="",G36=0),"",(B36-G36)/G36)
A37: =Watchlist!A37 | B37: =Watchlist!C37 | C37: 86.1395 | D37: =IF(OR(B37="",C37="",C37=0),"",B37-C37) | E37: =IF(OR(B37="",C37="",C37=0),"",(B37-C37)/C37) | G37: =Watchlist!F37 | H37: =IF(OR(B37="",G37="",G37=0),"",(B37-G37)/G37)
A38: =Watchlist!A38 | B38: =Watchlist!C38 | C38: 79.3005 | D38: =IF(OR(B38="",C38="",C38=0),"",B38-C38) | E38: =IF(OR(B38="",C38="",C38=0),"",(B38-C38)/C38) | G38: =Watchlist!F38 | H38: =IF(OR(B38="",G38="",G38=0),"",(B38-G38)/G38)
A39: =Watchlist!A39 | B39: =Watchlist!C39 | C39: 144.229 | D39: =IF(OR(B39="",C39="",C39=0),"",B39-C39) | E39: =IF(OR(B39="",C39="",C39=0),"",(B39-C39)/C39) | G39: =Watchlist!F39 | H39: =IF(OR(B39="",G39="",G39=0),"",(B39-G39)/G39)
A40: =Watchlist!A40 | B40: =Watchlist!C40 | C40: 29.7065 | D40: =IF(OR(B40="",C40="",C40=0),"",B40-C40) | E40: =IF(OR(B40="",C40="",C40=0),"",(B40-C40)/C40) | G40: =Watchlist!F40 | H40: =IF(OR(B40="",G40="",G40=0),"",(B40-G40)/G40)
A41: =Watchlist!A41 | B41: =Watchlist!C41 | C41: 273.7375 | D41: =IF(OR(B41="",C41="",C41=0),"",B41-C41) | E41: =IF(OR(B41="",C41="",C41=0),"",(B41-C41)/C41) | G41: =Watchlist!F41 | H41: =IF(OR(B41="",G41="",G41=0),"",(B41-G41)/G41)
A42: =Watchlist!A42 | B42: =Watchlist!C42 | C42: 296.8395 | D42: =IF(OR(B42="",C42="",C42=0),"",B42-C42) | E42: =IF(OR(B42="",C42="",C42=0),"",(B42-C42)/C42) | G42: =Watchlist!F42 | H42: =IF(OR(B42="",G42="",G42=0),"",(B42-G42)/G42)
A43: =Watchlist!A43 | B43: =Watchlist!C43 | C43: 277.0435 | D43: =IF(OR(B43="",C43="",C43=0),"",B43-C43) | E43: =IF(OR(B43="",C43="",C43=0),"",(B43-C43)/C43) | G43: =Watchlist!F43 | H43: =IF(OR(B43="",G43="",G43=0),"",(B43-G43)/G43)
... A48: =Watchlist!A48 | B48: =Watchlist!C48 | C48: 264.611 | D48: =IF(OR(B48="",C48="",C48=0),"",B48-C48) | E48: =IF(OR(B48="",C48="",C48=0),"",(B48-C48)/C48) | G48: =Watchlist!F48 | H48: =IF(OR(B48="",G48="",G48=0),"",(B48-G48)/G48)
A49: =Watchlist!A49 | B49: =Watchlist!C49 | G49: =Watchlist!F49 | H49: =IF(OR(B49="",G49="",G49=0),"",(B49-G49)/G49)
A50: =Watchlist!A50 | B50: =Watchlist!C50 | C50: 88.122 | D50: =IF(OR(B50="",C50="",C50=0),"",B50-C50) | E50: =IF(OR(B50="",C50="",C50=0),"",(B50-C50)/C50) | G50: =Watchlist!F50 | H50: =IF(OR(B50="",G50="",G50=0),"",(B50-G50)/G50)
A51: =Watchlist!A51 | B51: =Watchlist!C51 | C51: 324.809 | D51: =IF(OR(B51="",C51="",C51=0),"",B51-C51) | E51: =IF(OR(B51="",C51="",C51=0),"",(B51-C51)/C51) | G51: =Watchlist!F51 | H51: =IF(OR(B51="",G51="",G51=0),"",(B51-G51)/G51)
A52: =Watchlist!A52 | B52: =Watchlist!C52 | C52: 24.015 | D52: =IF(OR(B52="",C52="",C52=0),"",B52-C52) | E52: =IF(OR(B52="",C52="",C52=0),"",(B52-C52)/C52) | G52: =Watchlist!F52 | H52: =IF(OR(B52="",G52="",G52=0),"",(B52-G52)/G52)
A53: =Watchlist!A53 | B53: =Watchlist!C53 | C53: 269.7125 | D53: =IF(OR(B53="",C53="",C53=0),"",B53-C53) | E53: =IF(OR(B53="",C53="",C53=0),"",(B53-C53)/C53) | G53: =Watchlist!F53 | H53: =IF(OR(B53="",G53="",G53=0),"",(B53-G53)/G53)
...

Sheet Top 5
A1: Top 5 - Lowest % Change 20 MA Vs CMP
A2: Ranked by the smallest (most negative) % Change 20 MA Vs CMP from the Analysis sheet. Live formulas - updates automatically.
A4: Rank | B4: Symbol | C4: CMP | D4: Diff in % CMP & 20 DMA
A5: 1 | B5: =INDEX(Analysis!$A$5:$A$103,MATCH(D5,Analysis!$E$5:$E$103,0)) | C5: =INDEX(Analysis!$B$5:$B$103,MATCH(D5,Analysis!$E$5:$E$103,0)) | D5: =SMALL(Analysis!$E$5:$E$103,1)
A6: 2 | B6: =INDEX(Analysis!$A$5:$A$103,MATCH(D6,Analysis!$E$5:$E$103,0)) | C6: =INDEX(Analysis!$B$5:$B$103,MATCH(D6,Analysis!$E$5:$E$103,0)) | D6: =SMALL(Analysis!$E$5:$E$103,2)
A7: 3 | B7: =INDEX(Analysis!$A$5:$A$103,MATCH(D7,Analysis!$E$5:$E$103,0)) | C7: =INDEX(Analysis!$B$5:$B$103,MATCH(D7,Analysis!$E$5:$E$103,0)) | D7: =SMALL(Analysis!$E$5:$E$103,3)
A8: 4 | B8: =INDEX(Analysis!$A$5:$A$103,MATCH(D8,Analysis!$E$5:$E$103,0)) | C8: =INDEX(Analysis!$B$5:$B$103,MATCH(D8,Analysis!$E$5:$E$103,0)) | D8: =SMALL(Analysis!$E$5:$E$103,4)
A9: 5 | B9: =INDEX(Analysis!$A$5:$A$103,MATCH(D9,Analysis!$E$5:$E$103,0)) | C9: =INDEX(Analysis!$B$5:$B$103,MATCH(D9,Analysis!$E$5:$E$103,0)) | D9: =SMALL(Analysis!$E$5:$E$103,5)

Sheet Backtest
A1: Backtest - Buy Most-Fallen Stock, Sell at +6% (₹1,00,000 / 60 slots)
A2: Entry: next day's Open after signal. Exit: TARGET (day's High touches entry x 1.06) or MAX HOLD (forced exit at Close after 90 trading days). Max 60 concurrent positions, at most 1 new buy/day, unlimited sells/day. OPEN rows are marked-to-market at the last available close.
A4: Symbol | B4: Signal Date | C4: Signal % | D4: Entry Date | E4: Entry Price | F4: Exit Date | G4: Exit Price | H4: Return % | I4: Days to +6% | J4: Days to +3% | K4: Status | L4: Exit Reason | M4: Fixed Capital | N4: Fixed P&L | O4: Compound Capital Used | P4: Compound P&L | Q4: Last Price (open) | R4: Unrealized % | U4: Total Capital | W4: 100000
A5: MAHKTECH | B5: 45159 | C5: -0.062941196 | D5: 45160 | E5: 14.39 | F5: 45195 | G5: 15.2534 | H5: 0.06 | I5: 24 | J5: 4 | K5: CLOSED | L5: TARGET | M5: 1666.6667 | N5: 100 | O5: 1666.6667 | P5: 100 | U5: Slots | W5: 60
A6: HNGSNGBEES | B6: 45166 | C6: -0.036126675 | D6: 45167 | E6: 268.8 | F6: 45300 | G6: 242.97 | H6: -0.09609375 | K6: CLOSED | L6: MAX HOLD | M6: 1666.6667 | N6: -160.15625 | O6: 1666.6667 | P6: -160.15625 | U6: Capital / Slot | W6: 1666.6667
A7: MAHKTECH | B7: 45195 | C7: -0.032897887 | D7: 45196 | E7: 14.69 | F7: 45329 | G7: 12.83 | H7: -0.12661675 | K7: CLOSED | L7: MAX HOLD | M7: 1666.6667 | N7: -211.02791 | O7: 1666.6667 | P7: -211.02791 | U7: Max Hold Days | W7: 90
A8: PSUBNKBEES | B8: 45212 | C8: -0.022687305 | D8: 45215 | E8: 56.14 | F8: 45265 | G8: 59.5084 | H8: 0.06 | I8: 34 | J8: 21 | K8: CLOSED | L8: TARGET | M8: 1666.6667 | N8: 100 | O8: 1666.6667 | P8: 100 | U8: Entry Threshold | W8: -0.02
A9: PSUBNKIETF | B9: 45217 | C9: -0.025086013 | D9: 45218 | E9: 50.98 | F9: 45265 | G9: 54.0388 | H9: 0.06 | I9: 31 | J9: 18 | K9: CLOSED | L9: TARGET | M9: 1666.6667 | N9: 100 | O9: 1666.6667 | P9: 100 | U9: Total Trades | W9: 109
A10: HDFCLOWVOL | B10: 45222 | C10: -0.09486048 | D10: 45224 | E10: 14.7 | F10: 45238 | G10: 15.582 | H10: 0.06 | I10: 10 | J10: 0 | K10: CLOSED | L10: TARGET | M10: 1666.6667 | N10: 100 | O10: 1666.6667 | P10: 100 | U10: Closed / Open | W10: 103 / 6
A11: MIDCAP | B11: 45226 | C11: -0.035125572 | D11: 45229 | E11: 11.3 | F11: 45246 | G11: 11.978 | H11: 0.06 | I11: 13 | J11: 8 | K11: CLOSED | L11: TARGET | M11: 1666.6667 | N11: 100 | O11: 1666.6667 | P11: 100 | U11: Exits: Target / Max Hold | W11: 75 / 28
A12: HDFCNIFIT | B12: 45230 | C12: -0.030170392 | D12: 45231 | E12: 30.61 | F12: 45239 | G12: 32.4466 | H12: 0.06 | I12: 6 | J12: 4 | K12: CLOSED | L12: TARGET | M12: 1666.6667 | N12: 100 | O12: 1666.6667 | P12: 100 | U12: Fixed - Realized Profit | W12: 3534.1853
A13: PVTBANKADD | B13: 45231 | C13: -0.034105815 | D13: 45232 | E13: 22.35 | F13: 45264 | G13: 23.691 | H13: 0.06 | I13: 21 | J13: 2 | K13: CLOSED | L13: TARGET | M13: 1666.6667 | N13: 100 | O13: 1666.6667 | P13: 100 | U13: Fixed - Unrealized P&L | W13: -270.72363
A14: HNGSNGBEES | B14: 45306 | C14: -0.028892309 | D14: 45307 | E14: 239.51 | F14: 45351 | G14: 253.8806 | H14: 0.06 | I14: 31 | J14: 26 | K14: CLOSED | L14: TARGET | M14: 1666.6667 | N14: 100 | O14: 1666.6667 | P14: 100 | U14: Fixed - Ending Value | W14: 103263.46
A15: PVTBANIETF | B15: 45315 | C15: -0.052462527 | D15: 45316 | E15: 23.39 | F15: 45398 | G15: 24.7934 | H15: 0.06 | I15: 54 | J15: 8 | K15: CLOSED | L15: TARGET | M15: 1666.6667 | N15: 100 | O15: 1666.6667 | P15: 100 | U15: Fixed - Max Drawdown | W15: 0.031907926
A16: HDFCPVTBAN | B16: 45320 | C16: -0.034977946 | D16: 45321 | E16: 24.37 | F16: 45324 | G16: 25.8322 | H16: 0.06 | I16: 3 | J16: 3 | K16: CLOSED | L16: TARGET | M16: 1666.6667 | N16: 100 | O16: 1666.6667 | P16: 100 | U16: Compounding - Realized Profit | W16: 3501.606
A17: PVTBANKADD | B17: 45321 | C17: -0.032757446 | D17: 45322 | E17: 23.44 | F17: 45397 | G17: 24.8464 | H17: 0.06 | I17: 50 | J17: 44 | K17: CLOSED | L17: TARGET | M17: 1666.6667 | N17: 100 | O17: 1666.6667 | P17: 100 | U17: Compounding - Unrealized P&L | W17: -262.39018
A18: HDFCPVTBAN | B18: 45324 | C18: -0.021953191 | D18: 45327 | E18: 24.71 | F18: 45461 | G18: 25.18 | H18: 0.019020639 | J18: 81 | K18: CLOSED | L18: MAX HOLD | M18: 1666.6667 | N18: 31.701066 | O18: 1666.6667 | P18: 31.701066 | U18: Compounding - Ending Value | W18: 103239.22
A19: FMCGIETF | B19: 45335 | C19: -0.024916652 | D19: 45336 | E19: 55.5 | F19: 45422 | G19: 58.83 | H19: 0.06 | I19: 57 | J19: 54 | K19: CLOSED | L19: TARGET | M19: 1666.6667 | N19: 100 | O19: 1666.6667 | P19: 100 | U19: Compounding - Max Drawdown | W19: 0.031907926
A20: MOVALUE | B20: 45350 | C20: -0.021316473 | D20: 45351 | E20: 93.05 | F20: 45407 | G20: 98.633 | H20: 0.06 | I20: 36 | J20: 4 | K20: CLOSED | L20: TARGET | M20: 1666.6667 | N20: 100 | O20: 1666.6667 | P20: 100
A21: ITIETF | B21: 45356 | C21: -0.02691615 | D21: 45357 | E21: 40.5 | F21: 45492 | G21: 42.93 | H21: 0.06 | I21: 89 | J21: 85 | K21: CLOSED | L21: TARGET | M21: 1666.6667 | N21: 100 | O21: 1666.6667 | P21: 100
A22: HDFCSML250 | B22: 45362 | C22: -0.029341771 | D22: 45363 | E22: 147.2 | F22: 45397 | G22: 156.032 | H22: 0.06 | I22: 21 | J22: 15 | K22: CLOSED | L22: TARGET | M22: 1666.6667 | N22: 100 | O22: 1666.6667 | P22: 100
A23: CPSEETF | B23: 45366 | C23: -0.058586955 | D23: 45369 | E23: 78.6 | F23: 45385 | G23: 83.316 | H23: 0.06 | I23: 10 | J23: 8 | K23: CLOSED | L23: TARGET | M23: 1666.6667 | N23: 100 | O23: 1666.6667 | P23: 100
A24: HDFCNIFIT | B24: 45373 | C24: -0.047480067 | D24: 45377 | E24: 36.5 | F24: 45477 | G24: 38.69 | H24: 0.06 | I24: 67 | J24: 2 | K24: CLOSED | L24: TARGET | M24: 1666.6667 | N24: 100 | O24: 1666.6667 | P24: 100
A25: MON100 | B25: 45404 | C25: -0.03901663 | D25: 45405 | E25: 141.66 | F25: 45422 | G25: 150.1596 | H25: 0.06 | I25: 12 | J25: 3 | K25: CLOSED | L25: TARGET | M25: 1666.6667 | N25: 100 | O25: 1666.6667 | P25: 100
A26: PSUBNKIETF | B26: 45419 | C26: -0.022816064 | D26: 45420 | E26: 72.18 | F26: 45446 | G26: 76.5108 | H26: 0.06 | I26: 18 | J26: 11 | K26: CLOSED | L26: TARGET | M26: 1666.6667 | N26: 100 | O26: 1666.6667 | P26: 100
A27: FINIETF | B27: 45421 | C27: -0.035169492 | D27: 45422 | E27: 23.12 | F27: 45456 | G27: 24.5072 | H27: 0.06 | I27: 24 | J27: 10 | K27: CLOSED | L27: TARGET | M27: 1666.6667 | N27: 100 | O27: 1666.6667 | P27: 100
A28: SMALLCAP | B28: 45422 | C28: -0.028700433 | D28: 45425 | E28: 45.75 | F28: 45453 | G28: 48.495 | H28: 0.06 | I28: 20 | J28: 4 | K28: CLOSED | L28: TARGET | M28: 1666.6667 | N28: 100 | O28: 1666.6667 | P28: 100
A29: PSUBNKBEES | B29: 45426 | C29: -0.020103648 | D29: 45427 | E29: 79.49 | F29: 45446 | G29: 84.2594 | H29: 0.06 | I29: 13 | J29: 6 | K29: CLOSED | L29: TARGET | M29: 1666.6667 | N29: 100 | O29: 1666.6667 | P29: 100
A30: ICICIB22 | B30: 45447 | C30: -0.043321383 | D30: 45448 | E30: 104.8 | F30: 45449 | G30: 111.088 | H30: 0.06 | I30: 1 | J30: 1 | K30: CLOSED | L30: TARGET | M30: 1666.6667 | N30: 100 | O30: 1666.6667 | P30: 100
A31: CPSEETF | B31: 45448 | C31: -0.050247928 | D31: 45449 | E31: 86.1 | F31: 45453 | G31: 91.266 | H31: 0.06 | I31: 2 | J31: 0 | K31: CLOSED | L31: TARGET | M31: 1666.6667 | N31: 100 | O31: 1666.6667 | P31: 100
... A33: MAHKTECH | B33: 45482 | C33: -0.021858895 | D33: 45483 | E33: 13.96 | F33: 45561 | G33: 14.7976 | H33: 0.06 | I33: 54 | J33: 53 | K33: CLOSED | L33: TARGET | M33: 1666.6667 | N33: 100 | O33: 1666.6667 | P33: 100
A34: MOREALTY | B34: 45485 | C34: -0.020742734 | D34: 45488 | E34: 112.19 | F34: 45621 | G34: 102.75 | H34: -0.084142972 | K34: CLOSED | L34: MAX HOLD | M34: 1666.6667 | N34: -140.23829 | O34: 1666.6667 | P34: -140.23829
A35: MONQ50 | B35: 45496 | C35: -0.041792637 | D35: 45497 | E35: 67.97 | F35: 45607 | G35: 72.0482 | H35: 0.06 | I35: 76 | J35: 75 | K35: CLOSED | L35: TARGET | M35: 1666.6667 | N35: 100 | O35: 1666.6667 | P35: 100
A36: PSUBNKBEES | B36: 45517 | C36: -0.050418749 | D36: 45518 | E36: 76.59 | F36: 45650 | G36: 73.36 | H36: -0.042172607 | J36: 3 | K36: CLOSED | L36: MAX HOLD | M36: 1666.6667 | N36: -70.287679 | O36: 1666.6667 | P36: -70.287679
A37: PSUBNKIETF | B37: 45518 | C37: -0.050536837 | D37: 45520 | E37: 69.69 | F37: 45652 | G37: 66.88 | H37: -0.040321423 | J37: 75 | K37: CLOSED | L37: MAX HOLD | M37: 1666.6667 | N37: -67.202372 | O37: 1666.6667 | P37: -67.202372
A38: CPSEETF | B38: 45540 | C38: -0.023872938 | D38: 45541 | E38: 100 | F38: 45673 | G38: 84.55 | H38: -0.1545 | K38: CLOSED | L38: MAX HOLD | M38: 1666.6667 | N38: -257.5 | O38: 1666.6667 | P38: -257.5
A39: HDFCPSUBK | B39: 45546 | C39: -0.052958874 | D39: 45547 | E39: 67.19 | F39: 45630 | G39: 71.2214 | H39: 0.06 | I39: 56 | J39: 14 | K39: CLOSED | L39: TARGET | M39: 1666.6667 | N39: 100 | O39: 1666.6667 | P39: 100
A40: OILIETF | B40: 45548 | C40: -0.034941764 | D40: 45551 | E40: 12.94 | F40: 45681 | G40: 10.53 | H40: -0.1862442 | J40: 12 | K40: CLOSED | L40: MAX HOLD | M40: 1666.6667 | N40: -310.40701 | O40: 1666.6667 | P40: -310.40701
A41: MODEFENCE | B41: 45568 | C41: -0.027021898 | D41: 45569 | E41: 72.3 | F41: 45637 | G41: 76.638 | H41: 0.06 | I41: 46 | J41: 8 | K41: CLOSED | L41: TARGET | M41: 1666.6667 | N41: 100 | O41: 1666.6667 | P41: 100
A42: FMCGIETF | B42: 45574 | C42: -0.038043478 | D42: 45575 | E42: 66.06 | F42: 45705 | G42: 56.03 | H42: -0.15183167 | K42: CLOSED | L42: MAX HOLD | M42: 1666.6667 | N42: -253.05278 | O42: 1666.6667 | P42: -253.05278
...
